Workbook
Name NativeTimeline_Dia: #N/A
Name NativeTimeline_Dia1: #N/A
Name NativeTimeline_Dia11: #N/A
Name NativeTimeline_Dia111: #N/A
Name NativeTimeline_Dia2: #N/A
Name NativeTimeline_Dia21: #N/A

Sheet PROVISÃO 2026
C2: AGROPECUÁRIA ARAMBURU
B6: Rótulos de Linha | C6: JANEIRO | D6: FEVEREIRO | E6: MARÇO | F6: ABRIL | G6: MAIO | H6: JUNHO | I6: JULHO | J6: AGOSTO | K6: SETEMBRO | L6: OUTUBRO | M6: NOVEMBRO | N6: DEZEMBRO | O6: Total Geral
B7: 1.1 – Saldo Inicial | C7: 383789.58 | O7: 383789.58
B8: 1.2 – Receita de Arrendamento de Terras | C8: 960000 | E8: 1793031.1 | I8: 760234.22 | O8: 3513265.3
B9: 1.8 – Resgate de Aplicações | C9: 179865.44 | D9: 47205.93 | E9: 15920.67 | F9: 4768 | G9: 4768 | H9: 0 | I9: 0 | J9: 0 | K9: 0 | L9: 0 | M9: 0 | N9: 0 | O9: 252528.04
B10: 1.9 – Outros Recebimentos | C10: 1878 | O10: 1878
B11: 2.1 – Despesas Administrativas | C11: -33968.09 | D11: -18402.09 | E11: -6971.07 | F11: -51971.07 | G11: -198707 | H11: -6971.07 | I11: -53515.29 | J11: -7249.07 | K11: -126971.07 | L11: -61971.07 | M11: -9258.07 | N11: -9258.07 | O11: -585213.03
B12: 2.2 – Despesas com Pessoal | C12: -8126.78 | D12: -7926.78 | E12: -7926.78 | F12: -7926.78 | G12: -7926.78 | H12: -7926.78 | I12: -7926.78 | J12: -7926.78 | K12: -13893.45 | L12: -3436.36 | M12: -10426.78 | N12: -11923.14 | O12: -103293.97
B13: 2.3 – Operação da Propriedade | C13: -18852.23 | D13: -19016.93 | E13: -19016.93 | F13: -19016.93 | G13: -19016.93 | H13: -19016.93 | I13: -18892.73 | J13: -318738.93 | K13: -19016.93 | L13: -9016.93 | M13: -19016.93 | N13: -19016.93 | O13: -517636.26
B14: 2.4 – Serviços Terceirizados | C14: -70 | D14: -70 | E14: -70 | F14: -70 | G14: -70 | H14: -70 | I14: -70 | J14: -70 | K14: -70 | L14: -70 | M14: -70 | N14: -70 | O14: -840
B15: 2.5 – Financeiras e Bancárias | C15: -334.75 | D15: -334.75 | E15: -334.75 | F15: -334.75 | G15: -334.75 | H15: -156.5 | I15: -156.5 | J15: -156.5 | K15: -156.5 | L15: -156.5 | M15: -156.5 | N15: -156.5 | O15: -2769.25
B16: 2.6 – Investimentos em Capital | C16: -100000 | F16: -383638.43 | O16: -483638.43
B17: 2.7 – Investimentos em Imobilizado Operacional | C17: -179030.89 | D17: -47205.93 | E17: -15920.67 | F17: -4768 | G17: -4768 | O17: -251693.49
B18: 2.8 – Distribuição de Lucro / Saídas Pessoais | C18: -110898.43 | D18: -95882.15 | E18: -731538.86 | F18: -91092.05 | G18: -83595.44 | H18: -97547.8 | I18: -77110.04 | J18: -184529.18 | K18: -128066.17 | L18: -152528.31 | M18: -128154.04 | N18: -142702.46 | O18: -2023644.9
B19: 2.9 – Outras Saídas | C19: -1878 | O19: -1878
B20: Total Geral | C20: 1072373.8 | D20: -141632.7 | E20: 1027172.7 | F20: -554050.01 | G20: -309650.9 | H20: -131689.08 | I20: 602562.88 | J20: -518670.46 | K20: -288174.12 | L20: -227179.17 | M20: -167082.32 | N20: -183127.1 | O20: 180853.55
C23: DISTRIBUIÇÃO DE LUCRO
B27: Rótulos de Linha | C27: JANEIRO | D27: FEVEREIRO | E27: MARÇO | F27: ABRIL | G27: MAIO | H27: JUNHO | I27: JULHO | J27: AGOSTO | K27: SETEMBRO | L27: OUTUBRO | M27: NOVEMBRO | N27: DEZEMBRO | O27: Total Geral
B28: Ana Beatriz Ponte Fragelli | E28: 557991.07 | O28: 557991.07
B29: 1.6 - Contratos de Venda | E29: 557991.07 | O29: 557991.07
B30: Repasse Venda Soja 24/25 | E30: 557991.07 | O30: 557991.07
B31: Claudio Luiz Resta Fragelli | C31: 62771.64 | D31: 33169.7 | E31: 74147.2 | F31: 39418.96 | G31: 36267.34 | H31: 39719.7 | I31: 35781.94 | J31: 70290.84 | K31: 42355.33 | L31: 48717.47 | M31: 33185.7 | N31: 43019.7 | O31: 558845.52
B32: 1.1 - Imóvel | C32: 39559.35 | D32: 15616.54 | E32: 15616.54 | F32: 15616.54 | G32: 15616.54 | H32: 15616.54 | I32: 15616.54 | J32: 15616.54 | K32: 15616.54 | L32: 15616.54 | M32: 15616.54 | N32: 15616.54 | O32: 211341.29
B33: Reforma Programada | C33: 2000 | D33: 2000 | E33: 2000 | F33: 2000 | G33: 2000 | H33: 2000 | I33: 2000 | J33: 2000 | K33: 2000 | L33: 2000 | M33: 2000 | N33: 2000 | O33: 24000
B34: Parcelamento (Residência SC) | C34: 13616.54 | D34: 13616.54 | E34: 13616.54 | F34: 13616.54 | G34: 13616.54 | H34: 13616.54 | I34: 13616.54 | J34: 13616.54 | K34: 13616.54 | L34: 13616.54 | M34: 13616.54 | N34: 13616.54 | O34: 163398.48
B35: IPTU (Casa Vila Inventário) | C35: 1507.96 | O35: 1507.96
B36: IPTU (Forest House) | C36: 5102.87 | O36: 5102.87
B37: IPTU (R. Margina Humberlina Lima 80) | C37: 2280.61 | O37: 2280.61
B38: IPTU (R. Margina Humberlina Lima 90) | C38: 2287.21 | O38: 2287.21
B39: IPTU (Atmosphera) | C39: 10476.95 | O39: 10476.95
B40: IPTU (R. Appa 201) | C40: 2287.21 | O40: 2287.21
B41: 1.3 - Renda Mensal/Qualidade de Vida | C41: 4565.99 | D41: 4118.25 | E41: 48845.75 | F41: 4118.25 | G41: 4118.25 | H41: 14218.25 | I41: 4118.25 | J41: 40745.75 | K41: 12218.25 | L41: 21118.25 | M41: 4118.25 | N41: 14218.25 | O41: 176521.74
B42: Distribuição Fixa | C42: 3105 | D42: 3105 | E42: 3105 | F42: 3105 | G42: 3105 | H42: 3105 | I42: 3105 | J42: 3105 | K42: 3105 | L42: 3105 | M42: 3105 | N42: 3105 | O42: 37260
B43: Custos Emergenciais | C43: 300 | D43: 300 | E43: 300 | F43: 300 | G43: 300 | H43: 300 | I43: 300 | J43: 300 | K43: 300 | L43: 300 | M43: 300 | N43: 300 | O43: 3600
B44: Medicamentos | C44: 713.25 | D44: 713.25 | E44: 713.25 | F44: 713.25 | G44: 713.25 | H44: 713.25 | I44: 713.25 | J44: 713.25 | K44: 713.25 | L44: 713.25 | M44: 713.25 | N44: 713.25 | O44: 8559
B45: Tratamento Dentário | E45: 500 | H45: 2500 | K45: 500 | N45: 2500 | O45: 6000
B46: Troca de Celular | C46: 447.74 | O46: 447.74
B47: Viagem Internacional | E47: 36627.5 | J47: 36627.5 | O47: 73255
B48: Viagem Trimestral | E48: 7600 | H48: 7600 | K48: 7600 | N48: 7600 | O48: 30400
B49: Viagem Final de Ano | L49: 17000 | O49: 17000
...

Sheet Dados Bancários
B3: ANA BEATRIZ
B5: DADOS BANCÁRIOS
B7: 1.04 - Despesas Pessoais | C7: Conta Bancária (Pgto) | D7: Validação | E7: Observação
B8: Casan Águas e Saneamento (Residência SC) | C8: Nubank 0101 C/C 6254033-3 | D8: ( ) Sim ( ) Não
B9: Claro Internet (Residência SC) | C9: Nubank 0101 C/C 6254033-3 | D9: ( ) Sim ( ) Não
B10: Dedetização (Residência SC) | C10: Nubank 0101 C/C 6254033-3 | D10: ( ) Sim ( ) Não
B11: IPTU (Residência SC) | C11: Nubank 0101 C/C 6254033-3 | D11: ( ) Sim ( ) Não
B12: Jardineiro (Residência SC) | C12: Nubank 0101 C/C 6254033-3 | D12: ( ) Sim ( ) Não
B13: Limpeza Caixa de Gordura (Residência SC) | C13: Nubank 0101 C/C 6254033-3 | D13: ( ) Sim ( ) Não
B14: Limpeza Mensal (Residência SC) | C14: Nubank 0101 C/C 6254033-3 | D14: ( ) Sim ( ) Não
B15: Reforma Programada (Residência SC) | C15: Nubank 0101 C/C 6254033-3 | D15: ( ) Sim ( ) Não
B16: Taxa de Coleta Residual (Residência SC) | C16: Nubank 0101 C/C 6254033-3 | D16: ( ) Sim ( ) Não
B18: 1.06 - Contratos de Venda | C18: Conta Bancária (Pgto) | D18: Validação | E18: Observação
B19: Repasse Venda Soja 23/24 | C19: Inter 0001 C/C 12284789-0 | D19: ( ) Sim ( ) Não
B20: Repasse Venda Milho 24/24 | C20: Inter 0001 C/C 12284789-0 | D20: ( ) Sim ( ) Não
B21: Repasse Venda Soja 24/25 | C21: Inter 0001 C/C 12284789-0 | D21: ( ) Sim ( ) Não
B24: CLÁUDIO LUIZ
B26: DADOS BANCÁRIOS
B28: 1.01 - Imóvel | C28: Conta Bancária (Pgto) | D28: Validação | E28: Observação
B29: C.E.R IPTU | C29: Bradesco 3489 C/C 3154-2 | D29: ( ) Sim ( ) Não
B30: C.E.R Taxa Lixo | C30: Bradesco 3489 C/C 3154-2 | D30: ( ) Sim ( ) Não
B31: IPTU (Apto 01 Marechal Rondon) | C31: Bradesco 3489 C/C 3154-2 | D31: ( ) Sim ( ) Não
B32: IPTU (Casa Barão) | C32: Bradesco 3489 C/C 3154-2 | D32: ( ) Sim ( ) Não
B33: IPTU (Casa Fundos Marechal Rondon) | C33: Bradesco 3489 C/C 3154-2 | D33: ( ) Sim ( ) Não
B34: IPTU (Casa Vila Inventário) | C34: Bradesco 3489 C/C 3154-2 | D34: ( ) Sim ( ) Não
B35: IPTU (Forest House) | C35: Bradesco 3489 C/C 3154-2 | D35: ( ) Sim ( ) Não
B36: IPTU (R. Margina Humberlina Lima 80) | C36: Bradesco 3489 C/C 3154-2 | D36: ( ) Sim ( ) Não
B37: IPTU (R. Margina Humberlina Lima 90) | C37: Bradesco 3489 C/C 3154-2 | D37: ( ) Sim ( ) Não
B38: IPTU (Sala 01 Marechal Rondon) | C38: Bradesco 3489 C/C 3154-2 | D38: ( ) Sim ( ) Não
B39: ITR Estância Ivone | C39: Bradesco 3489 C/C 3154-2 | D39: ( ) Sim ( ) Não
B40: Parcelamento (Residência SC) | C40: Bradesco 3489 C/C 3154-2 | D40: ( ) Sim ( ) Não
... B42: Usucapião | C42: Bradesco 3489 C/C 3154-2 | D42: ( ) Sim ( ) Não
B43: 1.03 - Renda Mensal/Qualidade de Vida | C43: Conta Bancária (Pgto) | D43: Validação | E43: Observação
B44: Custos Emergenciais | C44: Bradesco 1375 C/C 242867-9 | D44: ( ) Sim ( ) Não
B45: Distribuição Fixa | C45: Bradesco 1375 C/C 242867-9 | D45: ( ) Sim ( ) Não
B46: Medicamento | C46: Bradesco 1375 C/C 242867-9 | D46: ( ) Sim ( ) Não
B47: Tratamento Dentário | C47: Bradesco 1375 C/C 242867-9 | D47: ( ) Sim ( ) Não
B48: Vacina | C48: Bradesco 1375 C/C 242867-9 | D48: ( ) Sim ( ) Não
B49: Troca de Celular | C49: B. Brasil cfragelli7@gmail.com | D49: ( ) Sim ( ) Não
B50: Viagem Final de Ano | C50: B. Brasil cfragelli7@gmail.com | D50: ( ) Sim ( ) Não
...

Sheet Classificação Financeira
B2: Classificações Financeiras - Agropecuária Aramburu Ltda
B5: Código | C5: Classificação | E5: Conta Contábil | G5: Conta Contábil + Centro de Custo | I5: Tipo de Despesa | K5: Forma de Pgto | M5: Conta Bancária | O5: Status
E7: Natureza da conta ou plano de contas, representa a finalidade da movimentação financeira, ou seja, o que está sendo pago ou recebido. | G7: Representa onde o recurso foi usado ou gerado, ou seja, qual unidade, fazenda, setor ou atividade originou aquela receita ou despesa.
B8: 1 – ENTRADAS | K8: Boleto | M8: Banco Cora (0001) | O8: Saldo inicial
B9: 1.1 | C9: Saldo Inicial | I9: Despesas Fixas | K9: Cartão de Débito | M9: Cooperativa Sicredi (0902) | O9: Recebido
B10: 1.1.1 | C10: Banco Cora | E10: 1 – ENTRADAS | G10: 1.1 SALDO INICIAL | I10: Despesas Variáveis | K10: Cartão de Crédito | M10: Cooperativa Sicredi (0913)
B11: 1.1.2 | C11: Cooperativa Sicredi | E11: 1.1 – Saldo Inicial | G11: 1.1.1 – Banco Cora | I11: Despesas Eventuais | K11: Débito Automático | M11: Banco Inter (0001-9) | O11: Pago
E12: 1.2 – Receita de Arrendamento de Terras | G12: 1.1.2 – Cooperativa Sicredi | I12: Despesas Periódicas | K12: Guia | O12: Repassado
B13: 1.2 | C13: Receita de Arrendamento de Terras | E13: 1.3 – Receita com Venda de Subprodutos | I13: - | K13: Pix | O13: Aplicado
B14: 1.2.1 | C14: Venda de Soja | E14: 1.4 – Receita com Venda de Animais | G14: 1.2 RECEITA DE ARRENDAMENTO DE TERRAS | K14: Transferência | O14: Resgatado
B15: 1.2.2 | C15: Venda de Milho | E15: 1.5 – Juros e Rendimentos de Aplicações | G15: 1.2.1 – Venda de Soja | K15: -
E16: 1.6 – Estorno de Pagamentos | G16: 1.2.2 – Venda de Milho | O16: A receber
B17: 1.3 | C17: Receita com Venda de Subprodutos | E17: 1.7 – Reembolsos Recebidos | O17: A pagar
B18: 1.3.1 | C18: Diversos | E18: 1.8 – Resgate de Aplicações | G18: 1.3 RECEITA COM VENDA DE SUBPRODUTOS | O18: A repassar
E19: 1.9 – Outros Recebimentos | G19: 1.3.1 – Diversos | O19: A aplicar
B20: 1.4 | C20: Receita com Venda de Animais | O20: A resgatar
B21: 1.4.1 | C21: Diversos | E21: 2 – SAÍDAS | G21: 1.4 RECEITA COM VENDA DE ANIMAIS
E22: 2.1 – Despesas Administrativas | G22: 1.4.1 – Diversos | O22: Provisionado
B23: 1.5 | C23: Juros e Rendimentos de Aplicações | E23: 2.2 – Despesas com Pessoal | O23: Aplicação
B24: 1.5.1 | C24: Cooperativa Sicredi | E24: 2.3 – Operação da Propriedade | G24: 1.5 JUROS E RENDIMENTOS DE APLICAÇÕES | O24: Resgate
B25: 1.5.2 | C25: Banco XP | E25: 2.4 – Serviços Terceirizados | G25: 1.5.1 – Cooperativa Sicredi | O25: Provisionado DV
E26: 2.5 – Financeiras e Bancárias | G26: 1.5.2 – Banco XP | O26: Provisionado DL
B27: 1.6 | C27: Estorno de Pagamentos | E27: 2.6 – Investimentos em Capital
B28: 1.6.1 | C28: Diversos | E28: 2.7 – Investimentos em Imobilizado Operacional | G28: 1.6 ESTORNO DE PAGAMENTOS
E29: 2.8 – Distribuição de Lucro / Saídas Pessoais | G29: 1.6.1 – Diversos
B30: 1.7 | C30: Reembolsos Recebidos | E30: 2.9 – Outras Saídas
B31: 1.7.1 | C31: Diversos | G31: 1.7 REEMBOLSO RECEBIDOS
G32: 1.7.1 – Diversos
B33: 1.8 | C33: Resgate de Aplicações
B34: 1.8.1 | C34: Cooperativa Sicredi | G34: 1.8 RESGATE DE APLICAÇÕES
B35: 1.8.2 | C35: Banco XP | G35: 1.8.1 – Cooperativa Sicredi
G36: 1.8.2 – Banco XP
B37: 1.9 | C37: Outros Recebimentos
B38: 1.9.1 | C38: Diversos | G38: 1.9 OUTROS RECEBIMENTOS
G39: 1.9.1 – Diversos
B40: 2 – SAÍDAS
B41: 2.1 | C41: Despesas Administrativa | G41: 2.1 DESPESAS ADMINISTRATIVAS
B42: 2.1.1 | C42: Honorários Contábeis | G42: 2.1.1 – Honorários Contábeis
B43: 2.1.2 | C43: Honorários Jurídicos | G43: 2.1.2 – Honorários Jurídicos
B44: 2.1.3 | C44: Despesas com Aluguel | G44: 2.1.3 – Despesas com Aluguel
...

Sheet Saldo Disponível
E9: CONTA CORRENTE | J9: C/C 0902 MJU | N9: C/C 0913 CGR | R9: INVEST | V9: INVEST EVOLUTIVO | Z9: CONTA CORRENTE | AD9: XP
E10: =SUMIFS(Aramburu_Mensal!$O$6:$O$1098,Aramburu_Mensal!$M$6:$M$1098,"Banco Cora (0001)",Aramburu_Mensal!$N$6:$N$1098,"saldo inicial")+SUMIFS(Aramburu_Mensal!$O$6:$O$1098,Aramburu_Mensal!$M$6:$M$1098,"Banco Cora (0001)",Aramburu_Mensal!$N$6:$N$1098,"pago")+SUMIFS(Aramburu_Mensal!$O$6:$O$1098,Aramburu_Mensal!$M$6:$M$1098,"Banco Cora (0001)",Aramburu_Mensal!$N$6:$N$1098,"Recebido")+SUMIFS(Aramburu_Mensal!$O$6:$O$1098,Aramburu_Mensal!$M$6:$M$1098,"Banco Cora (0001)",Aramburu_Mensal!$N$6:$N$1098,"Aplicado")+SUMIFS(Aramburu_Mensal!$O$6:$O$1098,Aramburu_Mensal!$M$6:$M$1098,"Banco Cora (0001)",Aramburu_Mensal!$N$6:$N$1098,"Resgatado")+SUMIFS(Aramburu_Mensal!$O$6:$O$1098,Aramburu_Mensal!$M$6:$M$1098,"Banco Cora (0001)",Aramburu_Mensal!$N$6:$N$1098,"Repassado") -> 1324843.3 | J10: =SUMIFS(Aramburu_Mensal!$O$6:$O$1098,Aramburu_Mensal!$M$6:$M$1098,"Cooperativa Sicredi (0902)",Aramburu_Mensal!$N$6:$N$1098,"saldo inicial")+SUMIFS(Aramburu_Mensal!$O$6:$O$1098,Aramburu_Mensal!$M$6:$M$1098,"Cooperativa Sicredi (0902)",Aramburu_Mensal!$N$6:$N$1098,"pago")+SUMIFS(Aramburu_Mensal!$O$6:$O$1098,Aramburu_Mensal!$M$6:$M$1098,"Cooperativa Sicredi (0902)",Aramburu_Mensal!$N$6:$N$1098,"Recebido")+SUMIFS(Aramburu_Mensal!$O$6:$O$1098,Aramburu_Mensal!$M$6:$M$1098,"Cooperativa Sicredi (0902)",Aramburu_Mensal!$N$6:$N$1098,"Aplicado")+SUMIFS(Aramburu_Mensal!$O$6:$O$1098,Aramburu_Mensal!$M$6:$M$1098,"Cooperativa Sicredi (0902)",Aramburu_Mensal!$N$6:$N$1098,"Resgatado")+SUMIFS(Aramburu_Mensal!$O$6:$O$1098,Aramburu_Mensal!$M$6:$M$1098,"Cooperativa Sicredi (0902)",Aramburu_Mensal!$N$6:$N$1098,"Repassado") -> -2.910383e-11 | N10: =SUMIFS(Aramburu_Mensal!$O$6:$O$1098,Aramburu_Mensal!$M$6:$M$1098,"Cooperativa Sicredi (0913)",Aramburu_Mensal!$N$6:$N$1098,"saldo inicial")+SUMIFS(Aramburu_Mensal!$O$6:$O$1098,Aramburu_Mensal!$M$6:$M$1098,"Cooperativa Sicredi (0913)",Aramburu_Mensal!$N$6:$N$1098,"pago")+SUMIFS(Aramburu_Mensal!$O$6:$O$1098,Aramburu_Mensal!$M$6:$M$1098,"Cooperativa Sicredi (0913)",Aramburu_Mensal!$N$6:$N$1098,"Recebido")+SUMIFS(Aramburu_Mensal!$O$6:$O$1098,Aramburu_Mensal!$M$6:$M$1098,"Cooperativa Sicredi (0913)",Aramburu_Mensal!$N$6:$N$1098,"Aplicado")+SUMIFS(Aramburu_Mensal!$O$6:$O$1098,Aramburu_Mensal!$M$6:$M$1098,"Cooperativa Sicredi (0913)",Aramburu_Mensal!$N$6:$N$1098,"Resgatado")+SUMIFS(Aramburu_Mensal!$O$6:$O$1098,Aramburu_Mensal!$M$6:$M$1098,"Cooperativa Sicredi (0913)",Aramburu_Mensal!$N$6:$N$1098,"Repassado") -> 1350.06 | R10: 187799.81 | V10: 132103.34 | Z10: 1000 | AD10: =1899472.09 -> 1899472.1
F15: JANEIRO | H15: FEVEREIRO | J15: MARÇO | L15: ABRIL | N15: MAIO | P15: JUNHO | R15: JULHO | T15: AGOSTO | V15: SETEMBRO | X15: OUTUBRO | Z15: NOVEMBRO | AB15: DEZEMBRO | AD15: TOTAL | AH15: FLUXO DE CAIXA 2026
D17: Saldo Inicial CORA (0001): | F17: =SUMIFS(Aramburu_Mensal!$O$6:$O$981,Aramburu_Mensal!$N$6:$N$981,"Saldo Inicial",Aramburu_Mensal!$M$6:$M$981,"Banco Cora (0001)") -> 383184.43 | H17: =F33 -> 1086493.1 | J17: =H33 -> 965011.08 | L17: =J33 -> 2274703.7 | N17: =L33 -> 1324843.3 | P17: =N33 -> 1052395.8 | R17: =P33 -> 917304.16 | T17: =R33 -> 1517793.9 | V17: =T33 -> 997050.36 | X17: =V33 -> 708271.3 | Z17: =X33 -> 479027.1 | AB17: =Z33 -> 308873.67
D18: Saldo Inicial SICREDI (0902): | F18: =SUMIFS(Aramburu_Mensal!$O$6:$O$981,Aramburu_Mensal!$N$6:$N$981,"Saldo Inicial",Aramburu_Mensal!$M$6:$M$981,"Cooperativa Sicredi (0902)") -> 51.15 | H18: =F34 -> 832.25 | J18: =H34 -> 713.35 | L18: =J34 -> 0 | N18: =L34 -> 0 | P18: =N34 -> 0 | R18: =P34 -> 0 | T18: =R34 -> 0 | V18: =T34 -> 0 | X18: =V34 -> 0 | Z18: =X34 -> 0 | AB18: =Z34 -> 0 | AH18: =AD21 -> 5078214.9 | AI18: Movimentações de Entradas
D19: Saldo Inicial SICREDI (0913): | F19: =SUMIFS(Aramburu_Mensal!$O$6:$O$981,Aramburu_Mensal!$N$6:$N$981,"Saldo Inicial",Aramburu_Mensal!$M$6:$M$981,"Cooperativa Sicredi (0913)") -> 100 | H19: =F35 -> 1819.56 | J19: =H35 -> 1663.06 | L19: =J35 -> 1506.56 | N19: =L35 -> 1350.06 | P19: =N35 -> 1181.06 | R19: =P35 -> 1012.07 | T19: =R35 -> 843.07 | V19: =T35 -> 674.07 | X19: =V35 -> 505.07 | Z19: =X35 -> 336.07 | AB19: =Z35 -> 167.07 | AH19: =AD26 -> -4953509.6 | AI19: Movimentações de Saídas
AH20: =SUM(AH18:AH19) -> 124705.34 | AI20: Saldo Final em Conta | 2025
D21: Entradas | E21: + | F21: =SUM(F22:F25) -> 2005604.9 | H21: =SUM(H23:H25) -> 86796.07 | J21: =SUM(J23:J25) -> 1902403.8 | L21: =SUM(L22:L25) -> 137968.85 | N21: =SUM(N22:N25) -> 129339.39 | P21: =SUM(P22:P25) -> 20446.87 | R21: =SUM(R22:R25) -> 775333.16 | T21: =SUM(T22:T25) -> 6060.12 | V21: =SUM(V22:V25) -> 6060.12 | X21: =SUM(X22:X25) -> 5913.37 | Z21: =SUM(Z22:Z25) -> 2288.37 | AB21: =SUM(AB22:AB25) -> 0 | AD21: =SUM(F21,H21,J21,L21,N21,P21,R21,T21,V21,X21,Z21,AB21) -> 5078214.9
D22: Saldo 2025 | F22: =SUMPRODUCT((Aramburu_Mensal!$C$6:$C$1098="janeiro")*(Aramburu_Mensal!$N$6:$N$1098="saldo inicial")*(Aramburu_Mensal!$O$6:$O$1098)) -> 383335.58 | H22: 0 | J22: 0 | L22: 0 | N22: 0 | P22: 0 | R22: 0 | T22: 0 | V22: 0 | X22: 0 | Z22: 0 | AB22: 0 | AD22: =SUM(F22:AC22) -> 383335.58
D23: Vendas | F23: =SUMPRODUCT((Aramburu_Mensal!$C$6:$C$1098="Janeiro")*(Aramburu_Mensal!$D$6:$D$1098="1.2 – Receita de Arrendamento de Terras")*((Aramburu_Mensal!$N$6:$N$1098="A receber")+(Aramburu_Mensal!$N$6:$N$1098="Recebido"))*(Aramburu_Mensal!$O$6:$O$1098)) -> 960000 | H23: =SUMPRODUCT((Aramburu_Mensal!$C$6:$C$1098="Fevereiro")*(Aramburu_Mensal!$D$6:$D$1098="1.2 – Receita de Arrendamento de Terras")*((Aramburu_Mensal!$N$6:$N$1098="A receber")+(Aramburu_Mensal!$N$6:$N$1098="Recebido"))*(Aramburu_Mensal!$O$6:$O$1098)) -> 0 | J23: =SUMPRODUCT((Aramburu_Mensal!$C$6:$C$1098="Março")*(Aramburu_Mensal!$D$6:$D$1098="1.2 – Receita de Arrendamento de Terras")*((Aramburu_Mensal!$N$6:$N$1098="A receber")+(Aramburu_Mensal!$N$6:$N$1098="Recebido"))*(Aramburu_Mensal!$O$6:$O$1098)) -> 1793031.1 | L23: =SUMPRODUCT((Aramburu_Mensal!$C$6:$C$1098="Abril")*(Aramburu_Mensal!$D$6:$D$1098="1.2 – Receita de Arrendamento de Terras")*((Aramburu_Mensal!$N$6:$N$1098="A receber")+(Aramburu_Mensal!$N$6:$N$1098="Recebido"))*(Aramburu_Mensal!$O$6:$O$1098)) -> 0 | N23: =SUMPRODUCT((Aramburu_Mensal!$C$6:$C$1098="Maio")*(Aramburu_Mensal!$D$6:$D$1098="1.2 – Receita de Arrendamento de Terras")*((Aramburu_Mensal!$N$6:$N$1098="A receber")+(Aramburu_Mensal!$N$6:$N$1098="Recebido"))*(Aramburu_Mensal!$O$6:$O$1098)) -> 0 | P23: =SUMPRODUCT((Aramburu_Mensal!$C$6:$C$1098="Junho")*(Aramburu_Mensal!$D$6:$D$1098="1.2 – Receita de Arrendamento de Terras")*((Aramburu_Mensal!$N$6:$N$1098="A receber")+(Aramburu_Mensal!$N$6:$N$1098="Recebido"))*(Aramburu_Mensal!$O$6:$O$1098)) -> 0 | R23: =SUMPRODUCT((Aramburu_Mensal!$C$6:$C$1098="Julho")*(Aramburu_Mensal!$D$6:$D$1098="1.2 – Receita de Arrendamento de Terras")*((Aramburu_Mensal!$N$6:$N$1098="A receber")+(Aramburu_Mensal!$N$6:$N$1098="Recebido"))*(Aramburu_Mensal!$O$6:$O$1098)) -> 760234.22 | T23: =SUMPRODUCT((Aramburu_Mensal!$C$6:$C$1098="Agosto")*(Aramburu_Mensal!$D$6:$D$1098="1.2 – Receita de Arrendamento de Terras")*((Aramburu_Mensal!$N$6:$N$1098="A receber")+(Aramburu_Mensal!$N$6:$N$1098="Recebido"))*(Aramburu_Mensal!$O$6:$O$1098)) -> 0 | V23: =SUMPRODUCT((Aramburu_Mensal!$C$6:$C$1098="Setembro")*(Aramburu_Mensal!$D$6:$D$1098="1.2 – Receita de Arrendamento de Terras")*((Aramburu_Mensal!$N$6:$N$1098="A receber")+(Aramburu_Mensal!$N$6:$N$1098="Recebido"))*(Aramburu_Mensal!$O$6:$O$1098)) -> 0 | X23: =SUMPRODUCT((Aramburu_Mensal!$C$6:$C$1098="Outubro")*(Aramburu_Mensal!$D$6:$D$1098="1.2 – Receita de Arrendamento de Terras")*((Aramburu_Mensal!$N$6:$N$1098="A receber")+(Aramburu_Mensal!$N$6:$N$1098="Recebido"))*(Aramburu_Mensal!$O$6:$O$1098)) -> 0 | Z23: =SUMPRODUCT((Aramburu_Mensal!$C$6:$C$1098="Novembro")*(Aramburu_Mensal!$D$6:$D$1098="1.2 – Receita de Arrendamento de Terras")*((Aramburu_Mensal!$N$6:$N$1098="A receber")+(Aramburu_Mensal!$N$6:$N$1098="Recebido"))*(Aramburu_Mensal!$O$6:$O$1098)) -> 0 | AB23: =SUMPRODUCT((Aramburu_Mensal!$C$6:$C$1098="Dezembro")*(Aramburu_Mensal!$D$6:$D$1098="1.2 – Receita de Arrendamento de Terras")*((Aramburu_Mensal!$N$6:$N$1098="A receber")+(Aramburu_Mensal!$N$6:$N$1098="Recebido"))*(Aramburu_Mensal!$O$6:$O$1098)) -> 0 | AD23: =SUM(F23:AC23) -> 3513265.3
D24: Investimentos (Resgate) | F24: =SUMPRODUCT((Aramburu_Mensal!$C$6:$C$1098="Janeiro")*((Aramburu_Mensal!$N$6:$N$1098="Resgate")+(Aramburu_Mensal!$N$6:$N$1098="A resgatar")+(Aramburu_Mensal!$N$6:$N$1098="Resgatado"))*(Aramburu_Mensal!$O$6:$O$1098)) -> 135614.8 | H24: =SUMPRODUCT((Aramburu_Mensal!$C$6:$C$1098="Fevereiro")*((Aramburu_Mensal!$N$6:$N$1098="Resgate")+(Aramburu_Mensal!$N$6:$N$1098="A resgatar")+(Aramburu_Mensal!$N$6:$N$1098="Resgatado"))*(Aramburu_Mensal!$O$6:$O$1098)) -> 86701.51 | J24: =SUMPRODUCT((Aramburu_Mensal!$C$6:$C$1098="Março")*((Aramburu_Mensal!$N$6:$N$1098="Resgate")+(Aramburu_Mensal!$N$6:$N$1098="A resgatar")+(Aramburu_Mensal!$N$6:$N$1098="Resgatado"))*(Aramburu_Mensal!$O$6:$O$1098)) -> 88899.32 | L24: =SUMPRODUCT((Aramburu_Mensal!$C$6:$C$1098="Abril")*((Aramburu_Mensal!$N$6:$N$1098="Resgate")+(Aramburu_Mensal!$N$6:$N$1098="A resgatar")+(Aramburu_Mensal!$N$6:$N$1098="Resgatado"))*(Aramburu_Mensal!$O$6:$O$1098)) -> 86068.75 | N24: =SUMPRODUCT((Aramburu_Mensal!$C$6:$C$1098="Maio")*((Aramburu_Mensal!$N$6:$N$1098="Resgate")+(Aramburu_Mensal!$N$6:$N$1098="A resgatar")+(Aramburu_Mensal!$N$6:$N$1098="Resgatado"))*(Aramburu_Mensal!$O$6:$O$1098)) -> 129339.39 | P24: =SUMPRODUCT((Aramburu_Mensal!$C$6:$C$1098="Junho")*((Aramburu_Mensal!$N$6:$N$1098="Resgate")+(Aramburu_Mensal!$N$6:$N$1098="A resgatar")+(Aramburu_Mensal!$N$6:$N$1098="Resgatado"))*(Aramburu_Mensal!$O$6:$O$1098)) -> 20446.87 | R24: =SUMPRODUCT((Aramburu_Mensal!$C$6:$C$1098="Julho")*((Aramburu_Mensal!$N$6:$N$1098="Resgate")+(Aramburu_Mensal!$N$6:$N$1098="A resgatar")+(Aramburu_Mensal!$N$6:$N$1098="Resgatado"))*(Aramburu_Mensal!$O$6:$O$1098)) -> 15098.94 | T24: =SUMPRODUCT((Aramburu_Mensal!$C$6:$C$1098="Agosto")*((Aramburu_Mensal!$N$6:$N$1098="Resgate")+(Aramburu_Mensal!$N$6:$N$1098="A resgatar")+(Aramburu_Mensal!$N$6:$N$1098="Resgatado"))*(Aramburu_Mensal!$O$6:$O$1098)) -> 6060.12 | V24: =SUMPRODUCT((Aramburu_Mensal!$C$6:$C$1098="Setembro")*((Aramburu_Mensal!$N$6:$N$1098="Resgate")+(Aramburu_Mensal!$N$6:$N$1098="A resgatar")+(Aramburu_Mensal!$N$6:$N$1098="Resgatado"))*(Aramburu_Mensal!$O$6:$O$1098)) -> 6060.12 | X24: =SUMPRODUCT((Aramburu_Mensal!$C$6:$C$1098="Outubro")*((Aramburu_Mensal!$N$6:$N$1098="Resgate")+(Aramburu_Mensal!$N$6:$N$1098="A resgatar")+(Aramburu_Mensal!$N$6:$N$1098="Resgatado"))*(Aramburu_Mensal!$O$6:$O$1098)) -> 5913.37 | Z24: =SUMPRODUCT((Aramburu_Mensal!$C$6:$C$1098="Novembro")*((Aramburu_Mensal!$N$6:$N$1098="Resgate")+(Aramburu_Mensal!$N$6:$N$1098="A resgatar")+(Aramburu_Mensal!$N$6:$N$1098="Resgatado"))*(Aramburu_Mensal!$O$6:$O$1098)) -> 2288.37 | AB24: =SUMPRODUCT((Aramburu_Mensal!$C$6:$C$1098="Dezembro")*((Aramburu_Mensal!$N$6:$N$1098="Resgate")+(Aramburu_Mensal!$N$6:$N$1098="A resgatar")+(Aramburu_Mensal!$N$6:$N$1098="Resgatado"))*(Aramburu_Mensal!$O$6:$O$1098)) -> 0 | AD24: =SUM(F24:AC24) -> 582491.56
D25: Outros Entradas | F25: =(SUMPRODUCT((Aramburu_Mensal!$C$6:$C$1098="Janeiro")*((Aramburu_Mensal!$N$6:$N$1098="A receber")+(Aramburu_Mensal!$N$6:$N$1098="Recebido"))*(Aramburu_Mensal!$O$6:$O$1098))-F23) -> 526654.48 | H25: =(SUMPRODUCT((Aramburu_Mensal!$C$6:$C$1098="Fevereiro")*((Aramburu_Mensal!$N$6:$N$1098="A receber")+(Aramburu_Mensal!$N$6:$N$1098="Recebido"))*(Aramburu_Mensal!$O$6:$O$1098))-H23) -> 94.56 | J25: =(SUMPRODUCT((Aramburu_Mensal!$C$6:$C$1098="Março")*((Aramburu_Mensal!$N$6:$N$1098="A receber")+(Aramburu_Mensal!$N$6:$N$1098="Recebido"))*(Aramburu_Mensal!$O$6:$O$1098))-J23) -> 20473.37 | L25: =(SUMPRODUCT((Aramburu_Mensal!$C$6:$C$1098="Abril")*((Aramburu_Mensal!$N$6:$N$1098="A receber")+(Aramburu_Mensal!$N$6:$N$1098="Recebido"))*(Aramburu_Mensal!$O$6:$O$1098))-L23) -> 51900.1 | N25: =(SUMPRODUCT((Aramburu_Mensal!$C$6:$C$1098="Maio")*((Aramburu_Mensal!$N$6:$N$1098="A receber")+(Aramburu_Mensal!$N$6:$N$1098="Recebido"))*(Aramburu_Mensal!$O$6:$O$1098))-N23) -> 0 | P25: =(SUMPRODUCT((Aramburu_Mensal!$C$6:$C$1098="Junho")*((Aramburu_Mensal!$N$6:$N$1098="A receber")+(Aramburu_Mensal!$N$6:$N$1098="Recebido"))*(Aramburu_Mensal!$O$6:$O$1098))-P23) -> 0 | R25: =(SUMPRODUCT((Aramburu_Mensal!$C$6:$C$1098="Julho")*((Aramburu_Mensal!$N$6:$N$1098="A receber")+(Aramburu_Mensal!$N$6:$N$1098="Recebido"))*(Aramburu_Mensal!$O$6:$O$1098))-R23) -> 0 | T25: =(SUMPRODUCT((Aramburu_Mensal!$C$6:$C$1098="Agosto")*((Aramburu_Mensal!$N$6:$N$1098="A receber")+(Aramburu_Mensal!$N$6:$N$1098="Recebido"))*(Aramburu_Mensal!$O$6:$O$1098))-T23) -> 0 | V25: =(SUMPRODUCT((Aramburu_Mensal!$C$6:$C$1098="Setembro")*((Aramburu_Mensal!$N$6:$N$1098="A receber")+(Aramburu_Mensal!$N$6:$N$1098="Recebido"))*(Aramburu_Mensal!$O$6:$O$1098))-V23) -> 0 | X25: =(SUMPRODUCT((Aramburu_Mensal!$C$6:$C$1098="Outubro")*((Aramburu_Mensal!$N$6:$N$1098="A receber")+(Aramburu_Mensal!$N$6:$N$1098="Recebido"))*(Aramburu_Mensal!$O$6:$O$1098))-X23) -> 0 | Z25: =(SUMPRODUCT((Aramburu_Mensal!$C$6:$C$1098="Novembro")*((Aramburu_Mensal!$N$6:$N$1098="A receber")+(Aramburu_Mensal!$N$6:$N$1098="Recebido"))*(Aramburu_Mensal!$O$6:$O$1098))-Z23) -> 0 | AB25: =(SUMPRODUCT((Aramburu_Mensal!$C$6:$C$1098="Dezembro")*((Aramburu_Mensal!$N$6:$N$1098="A receber")+(Aramburu_Mensal!$N$6:$N$1098="Recebido"))*(Aramburu_Mensal!$O$6:$O$1098))-AB23) -> 0 | AD25: =SUM(F25:AC25) -> 599122.51 | AH25: SALDOS 2026
D26: Saídas | E26: - | F26: =SUM(F27:F30) -> -916459.96 | H26: =SUM(H27:H30) -> -208553.48 | J26: =SUM(J27:J30) -> -593581.03 | L26: =SUM(L27:L30) -> -1087985.7 | N26: =SUM(N27:N30) -> -401955.86 | P26: =SUM(P27:P30) -> -155707.54 | R26: =SUM(R27:R30) -> -175012.39 | T26: =SUM(T27:T30) -> -526972.69 | V26: =SUM(V27:V30) -> -295008.18 | X26: =SUM(X27:X30) -> -235326.57 | Z26: =SUM(Z27:Z30) -> -172610.8 | AB26: =SUM(AB27:AB30) -> -184335.4 | AD26: =SUM(F26:AC26) -> -4953509.6
D27: Despesas Aramburu | F27: =SUMPRODUCT((Aramburu_Mensal!$C$6:$C$1098="janeiro")*((Aramburu_Mensal!$N$6:$N$1098="provisionado")+(Aramburu_Mensal!$N$6:$N$1098="a pagar")+(Aramburu_Mensal!$N$6:$N$1098="Pago")+(Aramburu_Mensal!$N$6:$N$1098="Provisionado DV"))*(Aramburu_Mensal!$O$6:$O$1098))-F30 -> -195848.44 | H27: =SUMPRODUCT((Aramburu_Mensal!$C$6:$C$1098="fevereiro")*((Aramburu_Mensal!$N$6:$N$1098="provisionado")+(Aramburu_Mensal!$N$6:$N$1098="a pagar")+(Aramburu_Mensal!$N$6:$N$1098="Pago")+(Aramburu_Mensal!$N$6:$N$1098="Provisionado DV"))*(Aramburu_Mensal!$O$6:$O$1098))-H30 -> -123484.94 | J27: =SUMPRODUCT((Aramburu_Mensal!$C$6:$C$1098="março")*((Aramburu_Mensal!$N$6:$N$1098="provisionado")+(Aramburu_Mensal!$N$6:$N$1098="a pagar")+(Aramburu_Mensal!$N$6:$N$1098="Pago")+(Aramburu_Mensal!$N$6:$N$1098="Provisionado DV"))*(Aramburu_Mensal!$O$6:$O$1098))-J30 -> -123078.9 | L27: =SUMPRODUCT((Aramburu_Mensal!$C$6:$C$1098="abril")*((Aramburu_Mensal!$N$6:$N$1098="provisionado")+(Aramburu_Mensal!$N$6:$N$1098="a pagar")+(Aramburu_Mensal!$N$6:$N$1098="Pago")+(Aramburu_Mensal!$N$6:$N$1098="Provisionado DV"))*(Aramburu_Mensal!$O$6:$O$1098))-L30 -> -222950.61 | N27: =SUMPRODUCT((Aramburu_Mensal!$C$6:$C$1098="maio")*((Aramburu_Mensal!$N$6:$N$1098="provisionado")+(Aramburu_Mensal!$N$6:$N$1098="a pagar")+(Aramburu_Mensal!$N$6:$N$1098="Pago")+(Aramburu_Mensal!$N$6:$N$1098="Provisionado DV"))*(Aramburu_Mensal!$O$6:$O$1098))-N30 -> -374284.45 | P27: =SUMPRODUCT((Aramburu_Mensal!$C$6:$C$1098="junho")*((Aramburu_Mensal!$N$6:$N$1098="provisionado")+(Aramburu_Mensal!$N$6:$N$1098="a pagar")+(Aramburu_Mensal!$N$6:$N$1098="Pago")+(Aramburu_Mensal!$N$6:$N$1098="Provisionado DV"))*(Aramburu_Mensal!$O$6:$O$1098))-P30 -> -62542.55 | R27: =SUMPRODUCT((Aramburu_Mensal!$C$6:$C$1098="julho")*((Aramburu_Mensal!$N$6:$N$1098="provisionado")+(Aramburu_Mensal!$N$6:$N$1098="a pagar")+(Aramburu_Mensal!$N$6:$N$1098="Pago")+(Aramburu_Mensal!$N$6:$N$1098="Provisionado DV"))*(Aramburu_Mensal!$O$6:$O$1098))-R30 -> -103614.65 | T27: =SUMPRODUCT((Aramburu_Mensal!$C$6:$C$1098="agosto")*((Aramburu_Mensal!$N$6:$N$1098="provisionado")+(Aramburu_Mensal!$N$6:$N$1098="a pagar")+(Aramburu_Mensal!$N$6:$N$1098="Pago")+(Aramburu_Mensal!$N$6:$N$1098="Provisionado DV"))*(Aramburu_Mensal!$O$6:$O$1098))-T30 -> -349438.55 | V27: =SUMPRODUCT((Aramburu_Mensal!$C$6:$C$1098="setembro")*((Aramburu_Mensal!$N$6:$N$1098="provisionado")+(Aramburu_Mensal!$N$6:$N$1098="a pagar")+(Aramburu_Mensal!$N$6:$N$1098="Pago")+(Aramburu_Mensal!$N$6:$N$1098="Provisionado DV"))*(Aramburu_Mensal!$O$6:$O$1098))-V30 -> -173937.05 | X27: =SUMPRODUCT((Aramburu_Mensal!$C$6:$C$1098="outubro")*((Aramburu_Mensal!$N$6:$N$1098="provisionado")+(Aramburu_Mensal!$N$6:$N$1098="a pagar")+(Aramburu_Mensal!$N$6:$N$1098="Pago")+(Aramburu_Mensal!$N$6:$N$1098="Provisionado DV"))*(Aramburu_Mensal!$O$6:$O$1098))-X30 -> -89793.3 | Z27: =SUMPRODUCT((Aramburu_Mensal!$C$6:$C$1098="novembro")*((Aramburu_Mensal!$N$6:$N$1098="provisionado")+(Aramburu_Mensal!$N$6:$N$1098="a pagar")+(Aramburu_Mensal!$N$6:$N$1098="Pago")+(Aramburu_Mensal!$N$6:$N$1098="Provisionado DV"))*(Aramburu_Mensal!$O$6:$O$1098))-Z30 -> -50609.3 | AB27: =SUMPRODUCT((Aramburu_Mensal!$C$6:$C$1098="dezembro")*((Aramburu_Mensal!$N$6:$N$1098="provisionado")+(Aramburu_Mensal!$N$6:$N$1098="a pagar")+(Aramburu_Mensal!$N$6:$N$1098="Pago")+(Aramburu_Mensal!$N$6:$N$1098="Provisionado DV"))*(Aramburu_Mensal!$O$6:$O$1098))-AB30 -> -49648.47 | AD27: =SUM(F27:AC27) -> -1919231.2
D28: Distribuição de Lucro | F28: =SUMPRODUCT((Aramburu_Mensal!$C$6:$C$1098="janeiro")*((Aramburu_Mensal!$N$6:$N$1098="provisionado dl")+(Aramburu_Mensal!$N$6:$N$1098="a repassar")+(Aramburu_Mensal!$N$6:$N$1098="repassado"))*(Aramburu_Mensal!$O$6:$O$1098)) -> -93957.02 | H28: =SUMPRODUCT((Aramburu_Mensal!$C$6:$C$1098="fevereiro")*((Aramburu_Mensal!$N$6:$N$1098="provisionado dl")+(Aramburu_Mensal!$N$6:$N$1098="a repassar")+(Aramburu_Mensal!$N$6:$N$1098="repassado"))*(Aramburu_Mensal!$O$6:$O$1098)) -> -84973.98 | J28: =SUMPRODUCT((Aramburu_Mensal!$C$6:$C$1098="março")*((Aramburu_Mensal!$N$6:$N$1098="provisionado dl")+(Aramburu_Mensal!$N$6:$N$1098="a repassar")+(Aramburu_Mensal!$N$6:$N$1098="repassado"))*(Aramburu_Mensal!$O$6:$O$1098)) -> -436231.06 | L28: =SUMPRODUCT((Aramburu_Mensal!$C$6:$C$1098="abril")*((Aramburu_Mensal!$N$6:$N$1098="provisionado dl")+(Aramburu_Mensal!$N$6:$N$1098="a repassar")+(Aramburu_Mensal!$N$6:$N$1098="repassado"))*(Aramburu_Mensal!$O$6:$O$1098)) -> -429950.56 | N28: =SUMPRODUCT((Aramburu_Mensal!$C$6:$C$1098="maio")*((Aramburu_Mensal!$N$6:$N$1098="provisionado dl")+(Aramburu_Mensal!$N$6:$N$1098="a repassar")+(Aramburu_Mensal!$N$6:$N$1098="repassado"))*(Aramburu_Mensal!$O$6:$O$1098)) -> -27671.41 | P28: =SUMPRODUCT((Aramburu_Mensal!$C$6:$C$1098="junho")*((Aramburu_Mensal!$N$6:$N$1098="provisionado dl")+(Aramburu_Mensal!$N$6:$N$1098="a repassar")+(Aramburu_Mensal!$N$6:$N$1098="repassado"))*(Aramburu_Mensal!$O$6:$O$1098)) -> -93164.99 | R28: =SUMPRODUCT((Aramburu_Mensal!$C$6:$C$1098="julho")*((Aramburu_Mensal!$N$6:$N$1098="provisionado dl")+(Aramburu_Mensal!$N$6:$N$1098="a repassar")+(Aramburu_Mensal!$N$6:$N$1098="repassado"))*(Aramburu_Mensal!$O$6:$O$1098)) -> -71397.74 | T28: =SUMPRODUCT((Aramburu_Mensal!$C$6:$C$1098="agosto")*((Aramburu_Mensal!$N$6:$N$1098="provisionado dl")+(Aramburu_Mensal!$N$6:$N$1098="a repassar")+(Aramburu_Mensal!$N$6:$N$1098="repassado"))*(Aramburu_Mensal!$O$6:$O$1098)) -> -177534.14 | V28: =SUMPRODUCT((Aramburu_Mensal!$C$6:$C$1098="setembro")*((Aramburu_Mensal!$N$6:$N$1098="provisionado dl")+(Aramburu_Mensal!$N$6:$N$1098="a repassar")+(Aramburu_Mensal!$N$6:$N$1098="repassado"))*(Aramburu_Mensal!$O$6:$O$1098)) -> -121071.13 | X28: =SUMPRODUCT((Aramburu_Mensal!$C$6:$C$1098="outubro")*((Aramburu_Mensal!$N$6:$N$1098="provisionado dl")+(Aramburu_Mensal!$N$6:$N$1098="a repassar")+(Aramburu_Mensal!$N$6:$N$1098="repassado"))*(Aramburu_Mensal!$O$6:$O$1098)) -> -145533.27 | Z28: =SUMPRODUCT((Aramburu_Mensal!$C$6:$C$1098="novembro")*((Aramburu_Mensal!$N$6:$N$1098="provisionado dl")+(Aramburu_Mensal!$N$6:$N$1098="a repassar")+(Aramburu_Mensal!$N$6:$N$1098="repassado"))*(Aramburu_Mensal!$O$6:$O$1098)) -> -122001.5 | AB28: =SUMPRODUCT((Aramburu_Mensal!$C$6:$C$1098="dezembro")*((Aramburu_Mensal!$N$6:$N$1098="provisionado dl")+(Aramburu_Mensal!$N$6:$N$1098="a repassar")+(Aramburu_Mensal!$N$6:$N$1098="repassado"))*(Aramburu_Mensal!$O$6:$O$1098)) -> -134686.93 | AD28: =SUM(F28:AC28) -> -1938173.7 | AH28: =AH20 -> 124705.34
D29: Investimentos (Aplicação) | F29: =SUMPRODUCT((Aramburu_Mensal!$C$6:$C$1098="janeiro")*((Aramburu_Mensal!$N$6:$N$1098="A aplicar")+(Aramburu_Mensal!$N$6:$N$1098="Aplicado")+(Aramburu_Mensal!$N$6:$N$1098="Aplicação"))*(Aramburu_Mensal!$O$6:$O$1098)) -> -400573.8 | H29: =SUMPRODUCT((Aramburu_Mensal!$C$6:$C$1098="fevereiro")*((Aramburu_Mensal!$N$6:$N$1098="A aplicar")+(Aramburu_Mensal!$N$6:$N$1098="Aplicado")+(Aramburu_Mensal!$N$6:$N$1098="Aplicação"))*(Aramburu_Mensal!$O$6:$O$1098)) -> 0 | J29: =SUMPRODUCT((Aramburu_Mensal!$C$6:$C$1098="março")*((Aramburu_Mensal!$N$6:$N$1098="A aplicar")+(Aramburu_Mensal!$N$6:$N$1098="Aplicado")+(Aramburu_Mensal!$N$6:$N$1098="Aplicação"))*(Aramburu_Mensal!$O$6:$O$1098)) -> -20140.28 | L29: =SUMPRODUCT((Aramburu_Mensal!$C$6:$C$1098="abril")*((Aramburu_Mensal!$N$6:$N$1098="A aplicar")+(Aramburu_Mensal!$N$6:$N$1098="Aplicado")+(Aramburu_Mensal!$N$6:$N$1098="Aplicação"))*(Aramburu_Mensal!$O$6:$O$1098)) -> -383184.43 | N29: =SUMPRODUCT((Aramburu_Mensal!$C$6:$C$1098="maio")*((Aramburu_Mensal!$N$6:$N$1098="A aplicar")+(Aramburu_Mensal!$N$6:$N$1098="Aplicado")+(Aramburu_Mensal!$N$6:$N$1098="Aplicação"))*(Aramburu_Mensal!$O$6:$O$1098)) -> 0 | P29: =SUMPRODUCT((Aramburu_Mensal!$C$6:$C$1098="junho")*((Aramburu_Mensal!$N$6:$N$1098="A aplicar")+(Aramburu_Mensal!$N$6:$N$1098="Aplicado")+(Aramburu_Mensal!$N$6:$N$1098="Aplicação"))*(Aramburu_Mensal!$O$6:$O$1098)) -> 0 | R29: =SUMPRODUCT((Aramburu_Mensal!$C$6:$C$1098="julho")*((Aramburu_Mensal!$N$6:$N$1098="A aplicar")+(Aramburu_Mensal!$N$6:$N$1098="Aplicado")+(Aramburu_Mensal!$N$6:$N$1098="Aplicação"))*(Aramburu_Mensal!$O$6:$O$1098)) -> 0 | T29: =SUMPRODUCT((Aramburu_Mensal!$C$6:$C$1098="agosto")*((Aramburu_Mensal!$N$6:$N$1098="A aplicar")+(Aramburu_Mensal!$N$6:$N$1098="Aplicado")+(Aramburu_Mensal!$N$6:$N$1098="Aplicação"))*(Aramburu_Mensal!$O$6:$O$1098)) -> 0 | V29: =SUMPRODUCT((Aramburu_Mensal!$C$6:$C$1098="setembro")*((Aramburu_Mensal!$N$6:$N$1098="A aplicar")+(Aramburu_Mensal!$N$6:$N$1098="Aplicado")+(Aramburu_Mensal!$N$6:$N$1098="Aplicação"))*(Aramburu_Mensal!$O$6:$O$1098)) -> 0 | X29: =SUMPRODUCT((Aramburu_Mensal!$C$6:$C$1098="outubro")*((Aramburu_Mensal!$N$6:$N$1098="A aplicar")+(Aramburu_Mensal!$N$6:$N$1098="Aplicado")+(Aramburu_Mensal!$N$6:$N$1098="Aplicação"))*(Aramburu_Mensal!$O$6:$O$1098)) -> 0 | Z29: =SUMPRODUCT((Aramburu_Mensal!$C$6:$C$1098="novembro")*((Aramburu_Mensal!$N$6:$N$1098="A aplicar")+(Aramburu_Mensal!$N$6:$N$1098="Aplicado")+(Aramburu_Mensal!$N$6:$N$1098="Aplicação"))*(Aramburu_Mensal!$O$6:$O$1098)) -> 0 | AB29: =SUMPRODUCT((Aramburu_Mensal!$C$6:$C$1098="dezembro")*((Aramburu_Mensal!$N$6:$N$1098="A aplicar")+(Aramburu_Mensal!$N$6:$N$1098="Aplicado")+(Aramburu_Mensal!$N$6:$N$1098="Aplicação"))*(Aramburu_Mensal!$O$6:$O$1098)) -> 0 | AD29: =SUM(F29:AC29) -> -803898.51
D30: Outras Saídas | F30: =SUMPRODUCT((Aramburu_Mensal!$C$6:$C$1098="janeiro")*(Aramburu_Mensal!$D$6:$D$1098="2.9 – Outras Saídas")*((Aramburu_Mensal!$N$6:$N$1098="provisionado")+(Aramburu_Mensal!$N$6:$N$1098="a pagar")+(Aramburu_Mensal!$N$6:$N$1098="Pago")+(Aramburu_Mensal!$N$6:$N$1098="Provisionado DV"))*(Aramburu_Mensal!$O$6:$O$1098)) -> -226080.7 | H30: =SUMPRODUCT((Aramburu_Mensal!$C$6:$C$1098="fevereiro")*(Aramburu_Mensal!$D$6:$D$1098="2.9 – Outras Saídas")*((Aramburu_Mensal!$N$6:$N$1098="provisionado")+(Aramburu_Mensal!$N$6:$N$1098="a pagar")+(Aramburu_Mensal!$N$6:$N$1098="Pago")+(Aramburu_Mensal!$N$6:$N$1098="Provisionado DV"))*(Aramburu_Mensal!$O$6:$O$1098)) -> -94.56 | J30: =SUMPRODUCT((Aramburu_Mensal!$C$6:$C$1098="março")*(Aramburu_Mensal!$D$6:$D$1098="2.9 – Outras Saídas")*((Aramburu_Mensal!$N$6:$N$1098="provisionado")+(Aramburu_Mensal!$N$6:$N$1098="a pagar")+(Aramburu_Mensal!$N$6:$N$1098="Pago")+(Aramburu_Mensal!$N$6:$N$1098="Provisionado DV"))*(Aramburu_Mensal!$O$6:$O$1098)) -> -14130.79 | L30: =SUMPRODUCT((Aramburu_Mensal!$C$6:$C$1098="abril")*(Aramburu_Mensal!$D$6:$D$1098="2.9 – Outras Saídas")*((Aramburu_Mensal!$N$6:$N$1098="provisionado")+(Aramburu_Mensal!$N$6:$N$1098="a pagar")+(Aramburu_Mensal!$N$6:$N$1098="Pago")+(Aramburu_Mensal!$N$6:$N$1098="Provisionado DV"))*(Aramburu_Mensal!$O$6:$O$1098)) -> -51900.1 | N30: =SUMPRODUCT((Aramburu_Mensal!$C$6:$C$1098="maio")*(Aramburu_Mensal!$D$6:$D$1098="2.9 – Outras Saídas")*((Aramburu_Mensal!$N$6:$N$1098="provisionado")+(Aramburu_Mensal!$N$6:$N$1098="a pagar")+(Aramburu_Mensal!$N$6:$N$1098="Pago")+(Aramburu_Mensal!$N$6:$N$1098="Provisionado DV"))*(Aramburu_Mensal!$O$6:$O$1098)) -> 0 | P30: =SUMPRODUCT((Aramburu_Mensal!$C$6:$C$1098="junho")*(Aramburu_Mensal!$D$6:$D$1098="2.9 – Outras Saídas")*((Aramburu_Mensal!$N$6:$N$1098="provisionado")+(Aramburu_Mensal!$N$6:$N$1098="a pagar")+(Aramburu_Mensal!$N$6:$N$1098="Pago")+(Aramburu_Mensal!$N$6:$N$1098="Provisionado DV"))*(Aramburu_Mensal!$O$6:$O$1098)) -> 0 | R30: =SUMPRODUCT((Aramburu_Mensal!$C$6:$C$1098="julho")*(Aramburu_Mensal!$D$6:$D$1098="2.9 – Outras Saídas")*((Aramburu_Mensal!$N$6:$N$1098="provisionado")+(Aramburu_Mensal!$N$6:$N$1098="a pagar")+(Aramburu_Mensal!$N$6:$N$1098="Pago")+(Aramburu_Mensal!$N$6:$N$1098="Provisionado DV"))*(Aramburu_Mensal!$O$6:$O$1098)) -> 0 | T30: =SUMPRODUCT((Aramburu_Mensal!$C$6:$C$1098="agosto")*(Aramburu_Mensal!$D$6:$D$1098="2.9 – Outras Saídas")*((Aramburu_Mensal!$N$6:$N$1098="provisionado")+(Aramburu_Mensal!$N$6:$N$1098="a pagar")+(Aramburu_Mensal!$N$6:$N$1098="Pago")+(Aramburu_Mensal!$N$6:$N$1098="Provisionado DV"))*(Aramburu_Mensal!$O$6:$O$1098)) -> 0 | V30: =SUMPRODUCT((Aramburu_Mensal!$C$6:$C$1098="setembro")*(Aramburu_Mensal!$D$6:$D$1098="2.9 – Outras Saídas")*((Aramburu_Mensal!$N$6:$N$1098="provisionado")+(Aramburu_Mensal!$N$6:$N$1098="a pagar")+(Aramburu_Mensal!$N$6:$N$1098="Pago")+(Aramburu_Mensal!$N$6:$N$1098="Provisionado DV"))*(Aramburu_Mensal!$O$6:$O$1098)) -> 0 | X30: =SUMPRODUCT((Aramburu_Mensal!$C$6:$C$1098="outubro")*(Aramburu_Mensal!$D$6:$D$1098="2.9 – Outras Saídas")*((Aramburu_Mensal!$N$6:$N$1098="provisionado")+(Aramburu_Mensal!$N$6:$N$1098="a pagar")+(Aramburu_Mensal!$N$6:$N$1098="Pago")+(Aramburu_Mensal!$N$6:$N$1098="Provisionado DV"))*(Aramburu_Mensal!$O$6:$O$1098)) -> 0 | Z30: =SUMPRODUCT((Aramburu_Mensal!$C$6:$C$1098="novembro")*(Aramburu_Mensal!$D$6:$D$1098="2.9 – Outras Saídas")*((Aramburu_Mensal!$N$6:$N$1098="provisionado")+(Aramburu_Mensal!$N$6:$N$1098="a pagar")+(Aramburu_Mensal!$N$6:$N$1098="Pago")+(Aramburu_Mensal!$N$6:$N$1098="Provisionado DV"))*(Aramburu_Mensal!$O$6:$O$1098)) -> 0 | AB30: =SUMPRODUCT((Aramburu_Mensal!$C$6:$C$1098="dezembro")*(Aramburu_Mensal!$D$6:$D$1098="2.9 – Outras Saídas")*((Aramburu_Mensal!$N$6:$N$1098="provisionado")+(Aramburu_Mensal!$N$6:$N$1098="a pagar")+(Aramburu_Mensal!$N$6:$N$1098="Pago")+(Aramburu_Mensal!$N$6:$N$1098="Provisionado DV"))*(Aramburu_Mensal!$O$6:$O$1098)) -> 0 | AD30: =SUM(F30:AC30) -> -292206.15 | AH30: =L45 -> -10614.41
D31: Saldo Final | E31: = | F31: =SUM(F21+F26) -> 1089144.9 | H31: =SUM(H21+H26) -> -121757.41 | J31: =SUM(J21+J26) -> 1308822.7 | L31: =SUM(L21+L26) -> -950016.85 | N31: =SUM(N21+N26) -> -272616.47 | P31: =SUM(P21+P26) -> -135260.67 | R31: =SUM(R21+R26) -> 600320.77 | T31: =SUM(T21+T26) -> -520912.57 | V31: =SUM(V21+V26) -> -288948.06 | X31: =SUM(X21+X26) -> -229413.2 | Z31: =SUM(Z21+Z26) -> -170322.43 | AB31: =SUM(AB21+AB26) -> -184335.4 | AD31: =SUM(AD21+AD26) -> 124705.34
D33: Saldo Final CORA (0001): | F33: =SUMPRODUCT((Aramburu_Mensal!$C$6:$C$1098="janeiro")*(Aramburu_Mensal!$M$6:$M$1098="Banco Cora (0001)")*((Aramburu_Mensal!$N$6:$N$1098="saldo inicial")+(Aramburu_Mensal!$N$6:$N$1098="pago")+(Aramburu_Mensal!$N$6:$N$1098="Recebido")+(Aramburu_Mensal!$N$6:$N$1098="Aplicação")+(Aramburu_Mensal!$N$6:$N$1098="Resgate")+(Aramburu_Mensal!$N$6:$N$1098="Repassado")+(Aramburu_Mensal!$N$6:$N$1098="Provisionado")+(Aramburu_Mensal!$N$6:$N$1098="Provisionado DV")+(Aramburu_Mensal!$N$6:$N$1098="A pagar")+(Aramburu_Mensal!$N$6:$N$1098="Provisionado DL")+(Aramburu_Mensal!$N$6:$N$1098="A repassar")+(Aramburu_Mensal!$N$6:$N$1098="A aplicar")+(Aramburu_Mensal!$N$6:$N$1098="A receber")+(Aramburu_Mensal!$N$6:$N$1098="A resgatar")+(Aramburu_Mensal!$N$6:$N$1098="Aplicado")+(Aramburu_Mensal!$N$6:$N$1098="Resgatado")),Aramburu_Mensal!$O$6:$O$1098) -> 1086493.1 | H33: =F33+SUMPRODUCT((Aramburu_Mensal!$C$6:$C$1098="fevereiro")*(Aramburu_Mensal!$M$6:$M$1098="Banco Cora (0001)")*((Aramburu_Mensal!$N$6:$N$1098="saldo inicial")+(Aramburu_Mensal!$N$6:$N$1098="pago")+(Aramburu_Mensal!$N$6:$N$1098="Recebido")+(Aramburu_Mensal!$N$6:$N$1098="Aplicação")+(Aramburu_Mensal!$N$6:$N$1098="Resgate")+(Aramburu_Mensal!$N$6:$N$1098="Repassado")+(Aramburu_Mensal!$N$6:$N$1098="Provisionado")+(Aramburu_Mensal!$N$6:$N$1098="Provisionado DV")+(Aramburu_Mensal!$N$6:$N$1098="A pagar")+(Aramburu_Mensal!$N$6:$N$1098="Provisionado DL")+(Aramburu_Mensal!$N$6:$N$1098="A repassar")+(Aramburu_Mensal!$N$6:$N$1098="A aplicar")+(Aramburu_Mensal!$N$6:$N$1098="A receber")+(Aramburu_Mensal!$N$6:$N$1098="A resgatar")+(Aramburu_Mensal!$N$6:$N$1098="Aplicado")+(Aramburu_Mensal!$N$6:$N$1098="Resgatado")),Aramburu_Mensal!$O$6:$O$1098) -> 965011.08 | J33: =H33+SUMPRODUCT((Aramburu_Mensal!$C$6:$C$1098="março")*(Aramburu_Mensal!$M$6:$M$1098="Banco Cora (0001)")*((Aramburu_Mensal!$N$6:$N$1098="saldo inicial")+(Aramburu_Mensal!$N$6:$N$1098="pago")+(Aramburu_Mensal!$N$6:$N$1098="Recebido")+(Aramburu_Mensal!$N$6:$N$1098="Aplicação")+(Aramburu_Mensal!$N$6:$N$1098="Resgate")+(Aramburu_Mensal!$N$6:$N$1098="Repassado")+(Aramburu_Mensal!$N$6:$N$1098="Provisionado")+(Aramburu_Mensal!$N$6:$N$1098="Provisionado DV")+(Aramburu_Mensal!$N$6:$N$1098="A pagar")+(Aramburu_Mensal!$N$6:$N$1098="Provisionado DL")+(Aramburu_Mensal!$N$6:$N$1098="A repassar")+(Aramburu_Mensal!$N$6:$N$1098="A aplicar")+(Aramburu_Mensal!$N$6:$N$1098="A receber")+(Aramburu_Mensal!$N$6:$N$1098="A resgatar")+(Aramburu_Mensal!$N$6:$N$1098="Aplicado")+(Aramburu_Mensal!$N$6:$N$1098="Resgatado")),Aramburu_Mensal!$O$6:$O$1098) -> 2274703.7 | L33: =J33+SUMPRODUCT((Aramburu_Mensal!$C$6:$C$1098="abril")*(Aramburu_Mensal!$M$6:$M$1098="Banco Cora (0001)")*((Aramburu_Mensal!$N$6:$N$1098="saldo inicial")+(Aramburu_Mensal!$N$6:$N$1098="pago")+(Aramburu_Mensal!$N$6:$N$1098="Recebido")+(Aramburu_Mensal!$N$6:$N$1098="Aplicação")+(Aramburu_Mensal!$N$6:$N$1098="Resgate")+(Aramburu_Mensal!$N$6:$N$1098="Repassado")+(Aramburu_Mensal!$N$6:$N$1098="Provisionado")+(Aramburu_Mensal!$N$6:$N$1098="Provisionado DV")+(Aramburu_Mensal!$N$6:$N$1098="A pagar")+(Aramburu_Mensal!$N$6:$N$1098="Provisionado DL")+(Aramburu_Mensal!$N$6:$N$1098="A repassar")+(Aramburu_Mensal!$N$6:$N$1098="A aplicar")+(Aramburu_Mensal!$N$6:$N$1098="A receber")+(Aramburu_Mensal!$N$6:$N$1098="A resgatar")+(Aramburu_Mensal!$N$6:$N$1098="Aplicado")+(Aramburu_Mensal!$N$6:$N$1098="Resgatado")),Aramburu_Mensal!$O$6:$O$1098) -> 1324843.3 | N33: =L33+SUMPRODUCT((Aramburu_Mensal!$C$6:$C$1098="maio")*(Aramburu_Mensal!$M$6:$M$1098="Banco Cora (0001)")*((Aramburu_Mensal!$N$6:$N$1098="saldo inicial")+(Aramburu_Mensal!$N$6:$N$1098="pago")+(Aramburu_Mensal!$N$6:$N$1098="Recebido")+(Aramburu_Mensal!$N$6:$N$1098="Aplicação")+(Aramburu_Mensal!$N$6:$N$1098="Resgate")+(Aramburu_Mensal!$N$6:$N$1098="Repassado")+(Aramburu_Mensal!$N$6:$N$1098="Provisionado")+(Aramburu_Mensal!$N$6:$N$1098="Provisionado DV")+(Aramburu_Mensal!$N$6:$N$1098="A pagar")+(Aramburu_Mensal!$N$6:$N$1098="Provisionado DL")+(Aramburu_Mensal!$N$6:$N$1098="A repassar")+(Aramburu_Mensal!$N$6:$N$1098="A aplicar")+(Aramburu_Mensal!$N$6:$N$1098="A receber")+(Aramburu_Mensal!$N$6:$N$1098="A resgatar")+(Aramburu_Mensal!$N$6:$N$1098="Aplicado")+(Aramburu_Mensal!$N$6:$N$1098="Resgatado")),Aramburu_Mensal!$O$6:$O$1098) -> 1052395.8 | P33: =N33+SUMPRODUCT((Aramburu_Mensal!$C$6:$C$1098="junho")*(Aramburu_Mensal!$M$6:$M$1098="Banco Cora (0001)")*((Aramburu_Mensal!$N$6:$N$1098="saldo inicial")+(Aramburu_Mensal!$N$6:$N$1098="pago")+(Aramburu_Mensal!$N$6:$N$1098="Recebido")+(Aramburu_Mensal!$N$6:$N$1098="Aplicação")+(Aramburu_Mensal!$N$6:$N$1098="Resgate")+(Aramburu_Mensal!$N$6:$N$1098="Repassado")+(Aramburu_Mensal!$N$6:$N$1098="Provisionado")+(Aramburu_Mensal!$N$6:$N$1098="Provisionado DV")+(Aramburu_Mensal!$N$6:$N$1098="A pagar")+(Aramburu_Mensal!$N$6:$N$1098="Provisionado DL")+(Aramburu_Mensal!$N$6:$N$1098="A repassar")+(Aramburu_Mensal!$N$6:$N$1098="A aplicar")+(Aramburu_Mensal!$N$6:$N$1098="A receber")+(Aramburu_Mensal!$N$6:$N$1098="A resgatar")+(Aramburu_Mensal!$N$6:$N$1098="Aplicado")+(Aramburu_Mensal!$N$6:$N$1098="Resgatado")),Aramburu_Mensal!$O$6:$O$1098) -> 917304.16 | R33: =P33+SUMPRODUCT((Aramburu_Mensal!$C$6:$C$1098="julho")*(Aramburu_Mensal!$M$6:$M$1098="Banco Cora (0001)")*((Aramburu_Mensal!$N$6:$N$1098="saldo inicial")+(Aramburu_Mensal!$N$6:$N$1098="pago")+(Aramburu_Mensal!$N$6:$N$1098="Recebido")+(Aramburu_Mensal!$N$6:$N$1098="Aplicação")+(Aramburu_Mensal!$N$6:$N$1098="Resgate")+(Aramburu_Mensal!$N$6:$N$1098="Repassado")+(Aramburu_Mensal!$N$6:$N$1098="Provisionado")+(Aramburu_Mensal!$N$6:$N$1098="Provisionado DV")+(Aramburu_Mensal!$N$6:$N$1098="A pagar")+(Aramburu_Mensal!$N$6:$N$1098="Provisionado DL")+(Aramburu_Mensal!$N$6:$N$1098="A repassar")+(Aramburu_Mensal!$N$6:$N$1098="A aplicar")+(Aramburu_Mensal!$N$6:$N$1098="A receber")+(Aramburu_Mensal!$N$6:$N$1098="A resgatar")+(Aramburu_Mensal!$N$6:$N$1098="Aplicado")+(Aramburu_Mensal!$N$6:$N$1098="Resgatado")),Aramburu_Mensal!$O$6:$O$1098) -> 1517793.9 | T33: =R33+SUMPRODUCT((Aramburu_Mensal!$C$6:$C$1098="agosto")*(Aramburu_Mensal!$M$6:$M$1098="Banco Cora (0001)")*((Aramburu_Mensal!$N$6:$N$1098="saldo inicial")+(Aramburu_Mensal!$N$6:$N$1098="pago")+(Aramburu_Mensal!$N$6:$N$1098="Recebido")+(Aramburu_Mensal!$N$6:$N$1098="Aplicação")+(Aramburu_Mensal!$N$6:$N$1098="Resgate")+(Aramburu_Mensal!$N$6:$N$1098="Repassado")+(Aramburu_Mensal!$N$6:$N$1098="Provisionado")+(Aramburu_Mensal!$N$6:$N$1098="Provisionado DV")+(Aramburu_Mensal!$N$6:$N$1098="A pagar")+(Aramburu_Mensal!$N$6:$N$1098="Provisionado DL")+(Aramburu_Mensal!$N$6:$N$1098="A repassar")+(Aramburu_Mensal!$N$6:$N$1098="A aplicar")+(Aramburu_Mensal!$N$6:$N$1098="A receber")+(Aramburu_Mensal!$N$6:$N$1098="A resgatar")+(Aramburu_Mensal!$N$6:$N$1098="Aplicado")+(Aramburu_Mensal!$N$6:$N$1098="Resgatado")),Aramburu_Mensal!$O$6:$O$1098) -> 997050.36 | V33: =T33+SUMPRODUCT((Aramburu_Mensal!$C$6:$C$1098="setembro")*(Aramburu_Mensal!$M$6:$M$1098="Banco Cora (0001)")*((Aramburu_Mensal!$N$6:$N$1098="saldo inicial")+(Aramburu_Mensal!$N$6:$N$1098="pago")+(Aramburu_Mensal!$N$6:$N$1098="Recebido")+(Aramburu_Mensal!$N$6:$N$1098="Aplicação")+(Aramburu_Mensal!$N$6:$N$1098="Resgate")+(Aramburu_Mensal!$N$6:$N$1098="Repassado")+(Aramburu_Mensal!$N$6:$N$1098="Provisionado")+(Aramburu_Mensal!$N$6:$N$1098="Provisionado DV")+(Aramburu_Mensal!$N$6:$N$1098="A pagar")+(Aramburu_Mensal!$N$6:$N$1098="Provisionado DL")+(Aramburu_Mensal!$N$6:$N$1098="A repassar")+(Aramburu_Mensal!$N$6:$N$1098="A aplicar")+(Aramburu_Mensal!$N$6:$N$1098="A receber")+(Aramburu_Mensal!$N$6:$N$1098="A resgatar")+(Aramburu_Mensal!$N$6:$N$1098="Aplicado")+(Aramburu_Mensal!$N$6:$N$1098="Resgatado")),Aramburu_Mensal!$O$6:$O$1098) -> 708271.3 | X33: =V33+SUMPRODUCT((Aramburu_Mensal!$C$6:$C$1098="outubro")*(Aramburu_Mensal!$M$6:$M$1098="Banco Cora (0001)")*((Aramburu_Mensal!$N$6:$N$1098="saldo inicial")+(Aramburu_Mensal!$N$6:$N$1098="pago")+(Aramburu_Mensal!$N$6:$N$1098="Recebido")+(Aramburu_Mensal!$N$6:$N$1098="Aplicação")+(Aramburu_Mensal!$N$6:$N$1098="Resgate")+(Aramburu_Mensal!$N$6:$N$1098="Repassado")+(Aramburu_Mensal!$N$6:$N$1098="Provisionado")+(Aramburu_Mensal!$N$6:$N$1098="Provisionado DV")+(Aramburu_Mensal!$N$6:$N$1098="A pagar")+(Aramburu_Mensal!$N$6:$N$1098="Provisionado DL")+(Aramburu_Mensal!$N$6:$N$1098="A repassar")+(Aramburu_Mensal!$N$6:$N$1098="A aplicar")+(Aramburu_Mensal!$N$6:$N$1098="A receber")+(Aramburu_Mensal!$N$6:$N$1098="A resgatar")+(Aramburu_Mensal!$N$6:$N$1098="Aplicado")+(Aramburu_Mensal!$N$6:$N$1098="Resgatado")),Aramburu_Mensal!$O$6:$O$1098) -> 479027.1 | Z33: =X33+SUMPRODUCT((Aramburu_Mensal!$C$6:$C$1098="novembro")*(Aramburu_Mensal!$M$6:$M$1098="Banco Cora (0001)")*((Aramburu_Mensal!$N$6:$N$1098="saldo inicial")+(Aramburu_Mensal!$N$6:$N$1098="pago")+(Aramburu_Mensal!$N$6:$N$1098="Recebido")+(Aramburu_Mensal!$N$6:$N$1098="Aplicação")+(Aramburu_Mensal!$N$6:$N$1098="Resgate")+(Aramburu_Mensal!$N$6:$N$1098="Repassado")+(Aramburu_Mensal!$N$6:$N$1098="Provisionado")+(Aramburu_Mensal!$N$6:$N$1098="Provisionado DV")+(Aramburu_Mensal!$N$6:$N$1098="A pagar")+(Aramburu_Mensal!$N$6:$N$1098="Provisionado DL")+(Aramburu_Mensal!$N$6:$N$1098="A repassar")+(Aramburu_Mensal!$N$6:$N$1098="A aplicar")+(Aramburu_Mensal!$N$6:$N$1098="A receber")+(Aramburu_Mensal!$N$6:$N$1098="A resgatar")+(Aramburu_Mensal!$N$6:$N$1098="Aplicado")+(Aramburu_Mensal!$N$6:$N$1098="Resgatado")),Aramburu_Mensal!$O$6:$O$1098) -> 308873.67 | AB33: =Z33+SUMPRODUCT((Aramburu_Mensal!$C$6:$C$1098="dezembro")*(Aramburu_Mensal!$M$6:$M$1098="Banco Cora (0001)")*((Aramburu_Mensal!$N$6:$N$1098="saldo inicial")+(Aramburu_Mensal!$N$6:$N$1098="pago")+(Aramburu_Mensal!$N$6:$N$1098="Recebido")+(Aramburu_Mensal!$N$6:$N$1098="Aplicação")+(Aramburu_Mensal!$N$6:$N$1098="Resgate")+(Aramburu_Mensal!$N$6:$N$1098="Repassado")+(Aramburu_Mensal!$N$6:$N$1098="Provisionado")+(Aramburu_Mensal!$N$6:$N$1098="Provisionado DV")+(Aramburu_Mensal!$N$6:$N$1098="A pagar")+(Aramburu_Mensal!$N$6:$N$1098="Provisionado DL")+(Aramburu_Mensal!$N$6:$N$1098="A repassar")+(Aramburu_Mensal!$N$6:$N$1098="A aplicar")+(Aramburu_Mensal!$N$6:$N$1098="A receber")+(Aramburu_Mensal!$N$6:$N$1098="A resgatar")+(Aramburu_Mensal!$N$6:$N$1098="Aplicado")+(Aramburu_Mensal!$N$6:$N$1098="Resgatado")),Aramburu_Mensal!$O$6:$O$1098) -> 124707.27
